ERROR 2019-11-13 00:15:04,502 root : Ah, my... Bad news. Look yourself:
HTTPConnectionPool(host='localhost', port=8000): Max retries exceeded with url: /health (Caused by NewConnectionError('<urllib3.connection.HTTPConnection object at 0x7f5fc2561080>: Failed to establish a new connection: [Errno 111] Connection refused'))
INFO 2019-11-13 00:16:37,738 root : Сервер доступний. Час на сервері: 2019-11-12 22:16:37:68
INFO 2019-11-13 00:16:37,738 root : Запитувана сторінка: : /health/
INFO 2019-11-13 00:16:37,739 root : Відповідь сервера місти наступні поля:
INFO 2019-11-13 00:16:37,739 root : Ключ: date, Значення: 2019-11-12 22:16:37:68
INFO 2019-11-13 00:16:37,739 root : Ключ: current_page, Значення: /health/
INFO 2019-11-13 00:16:37,739 root : Ключ: server_info, Значення: ['Linux', 'nalyvaiko', '5.0.0-32-generic', '#34~18.04.2-Ubuntu SMP Thu Oct 10 10:36:02 UTC 2019', 'x86_64']
INFO 2019-11-13 00:16:37,739 root : Ключ: client_info, Значення: python-requests/2.22.0
